<?xml version="1.0" encoding="UTF-8"?>
<testng-results ignored="0" total="8" passed="5" failed="3" skipped="0">
  <reporter-output>
  </reporter-output>
  <suite started-at="2018-11-27T09:03:22Z" name="Default suite" finished-at="2018-11-27T09:03:36Z" duration-ms="13770">
    <groups>
    </groups>
    <test started-at="2018-11-27T09:03:22Z" name="Default test" finished-at="2018-11-27T09:03:36Z" duration-ms="13770">
      <class name="Railway.LoginTest">
        <test-method is-config="true" signature="beforeClass()[pri:0, instance:Railway.LoginTest@76055d02]" started-at="2018-11-27T09:03:22Z" name="beforeClass" finished-at="2018-11-27T09:03:29Z" duration-ms="6557" status="PASS">
          <reporter-output>
          </reporter-output>
        </test-method> <!-- beforeClass -->
        <test-method signature="TC01()[pri:0, instance:Railway.LoginTest@76055d02]" started-at="2018-11-27T09:03:29Z" name="TC01" description="User can log into Railway with valid username and password" finished-at="2018-11-27T09:03:29Z" duration-ms="938" status="PASS">
          <reporter-output>
          </reporter-output>
        </test-method> <!-- TC01 -->
        <test-method signature="TC02()[pri:0, instance:Railway.LoginTest@76055d02]" started-at="2018-11-27T09:03:30Z" name="TC02" description="User can&#039;t login with blank &#039;Username&#039; textbox" finished-at="2018-11-27T09:03:30Z" duration-ms="447" status="PASS">
          <reporter-output>
          </reporter-output>
        </test-method> <!-- TC02 -->
        <test-method signature="TC03()[pri:0, instance:Railway.LoginTest@76055d02]" started-at="2018-11-27T09:03:30Z" name="TC03" description="User cannot log into Railway with invalid password" finished-at="2018-11-27T09:03:30Z" duration-ms="542" status="FAIL">
          <exception class="java.lang.AssertionError">
            <message>
              <![CDATA[expected [There was a problem with your login and/or errors exist in your form.] but found [Invalid username or password. Please try again.]]]>
            </message>
            <full-stacktrace>
              <![CDATA[java.lang.AssertionError: expected [There was a problem with your login and/or errors exist in your form.] but found [Invalid username or password. Please try again.]
at org.testng.Assert.fail(Assert.java:96)
at org.testng.Assert.failNotEquals(Assert.java:776)
at org.testng.Assert.assertEqualsImpl(Assert.java:137)
at org.testng.Assert.assertEquals(Assert.java:118)
at org.testng.Assert.assertEquals(Assert.java:453)
at org.testng.Assert.assertEquals(Assert.java:463)
at Railway.LoginTest.TC03(LoginTest.java:38)
at java.base/jdk.internal.reflect.NativeMethodAccessorImpl.invoke0(Native Method)
at java.base/jdk.internal.reflect.NativeMethodAccessorImpl.invoke(NativeMethodAccessorImpl.java:62)
at java.base/jdk.internal.reflect.DelegatingMethodAccessorImpl.invoke(DelegatingMethodAccessorImpl.java:43)
at java.base/java.lang.reflect.Method.invoke(Method.java:566)
at org.testng.internal.MethodInvocationHelper.invokeMethod(MethodInvocationHelper.java:124)
at org.testng.internal.Invoker.invokeMethod(Invoker.java:580)
at org.testng.internal.Invoker.invokeTestMethod(Invoker.java:716)
at org.testng.internal.Invoker.invokeTestMethods(Invoker.java:988)
at org.testng.internal.TestMethodWorker.invokeTestMethods(TestMethodWorker.java:125)
at org.testng.internal.TestMethodWorker.run(TestMethodWorker.java:109)
at org.testng.TestRunner.privateRun(TestRunner.java:648)
at org.testng.TestRunner.run(TestRunner.java:505)
at org.testng.SuiteRunner.runTest(SuiteRunner.java:455)
at org.testng.SuiteRunner.runSequentially(SuiteRunner.java:450)
at org.testng.SuiteRunner.privateRun(SuiteRunner.java:415)
at org.testng.SuiteRunner.run(SuiteRunner.java:364)
at org.testng.SuiteRunnerWorker.runSuite(SuiteRunnerWorker.java:52)
at org.testng.SuiteRunnerWorker.run(SuiteRunnerWorker.java:84)
at org.testng.TestNG.runSuitesSequentially(TestNG.java:1208)
at org.testng.TestNG.runSuitesLocally(TestNG.java:1137)
at org.testng.TestNG.runSuites(TestNG.java:1049)
at org.testng.TestNG.run(TestNG.java:1017)
at org.testng.remote.AbstractRemoteTestNG.run(AbstractRemoteTestNG.java:114)
at org.testng.remote.RemoteTestNG.initAndRun(RemoteTestNG.java:251)
at org.testng.remote.RemoteTestNG.main(RemoteTestNG.java:77)
]]>
            </full-stacktrace>
          </exception> <!-- java.lang.AssertionError -->
          <reporter-output>
          </reporter-output>
        </test-method> <!-- TC03 -->
        <test-method signature="TC04()[pri:0, instance:Railway.LoginTest@76055d02]" started-at="2018-11-27T09:03:30Z" name="TC04" description="Login page displays when un-logged User clicks on &#039;Book ticket&#039; tab" finished-at="2018-11-27T09:03:31Z" duration-ms="187" status="PASS">
          <reporter-output>
          </reporter-output>
        </test-method> <!-- TC04 -->
        <test-method signature="TC05()[pri:0, instance:Railway.LoginTest@76055d02]" started-at="2018-11-27T09:03:31Z" name="TC05" description="System shows message when user enters wrong password several times" finished-at="2018-11-27T09:03:32Z" duration-ms="1689" status="FAIL">
          <exception class="java.lang.AssertionError">
            <message>
              <![CDATA[expected [You have used 4 out of 5 login attempts. After all 5 have been used, you will be unable to login for 15 minutes.] but found [Invalid username or password. Please try again.]]]>
            </message>
            <full-stacktrace>
              <![CDATA[java.lang.AssertionError: expected [You have used 4 out of 5 login attempts. After all 5 have been used, you will be unable to login for 15 minutes.] but found [Invalid username or password. Please try again.]
at org.testng.Assert.fail(Assert.java:96)
at org.testng.Assert.failNotEquals(Assert.java:776)
at org.testng.Assert.assertEqualsImpl(Assert.java:137)
at org.testng.Assert.assertEquals(Assert.java:118)
at org.testng.Assert.assertEquals(Assert.java:453)
at org.testng.Assert.assertEquals(Assert.java:463)
at Railway.LoginTest.TC05(LoginTest.java:53)
at java.base/jdk.internal.reflect.NativeMethodAccessorImpl.invoke0(Native Method)
at java.base/jdk.internal.reflect.NativeMethodAccessorImpl.invoke(NativeMethodAccessorImpl.java:62)
at java.base/jdk.internal.reflect.DelegatingMethodAccessorImpl.invoke(DelegatingMethodAccessorImpl.java:43)
at java.base/java.lang.reflect.Method.invoke(Method.java:566)
at org.testng.internal.MethodInvocationHelper.invokeMethod(MethodInvocationHelper.java:124)
at org.testng.internal.Invoker.invokeMethod(Invoker.java:580)
at org.testng.internal.Invoker.invokeTestMethod(Invoker.java:716)
at org.testng.internal.Invoker.invokeTestMethods(Invoker.java:988)
at org.testng.internal.TestMethodWorker.invokeTestMethods(TestMethodWorker.java:125)
at org.testng.internal.TestMethodWorker.run(TestMethodWorker.java:109)
at org.testng.TestRunner.privateRun(TestRunner.java:648)
at org.testng.TestRunner.run(TestRunner.java:505)
at org.testng.SuiteRunner.runTest(SuiteRunner.java:455)
at org.testng.SuiteRunner.runSequentially(SuiteRunner.java:450)
at org.testng.SuiteRunner.privateRun(SuiteRunner.java:415)
at org.testng.SuiteRunner.run(SuiteRunner.java:364)
at org.testng.SuiteRunnerWorker.runSuite(SuiteRunnerWorker.java:52)
at org.testng.SuiteRunnerWorker.run(SuiteRunnerWorker.java:84)
at org.testng.TestNG.runSuitesSequentially(TestNG.java:1208)
at org.testng.TestNG.runSuitesLocally(TestNG.java:1137)
at org.testng.TestNG.runSuites(TestNG.java:1049)
at org.testng.TestNG.run(TestNG.java:1017)
at org.testng.remote.AbstractRemoteTestNG.run(AbstractRemoteTestNG.java:114)
at org.testng.remote.RemoteTestNG.initAndRun(RemoteTestNG.java:251)
at org.testng.remote.RemoteTestNG.main(RemoteTestNG.java:77)
]]>
            </full-stacktrace>
          </exception> <!-- java.lang.AssertionError -->
          <reporter-output>
          </reporter-output>
        </test-method> <!-- TC05 -->
        <test-method signature="TC06()[pri:0, instance:Railway.LoginTest@76055d02]" started-at="2018-11-27T09:03:32Z" name="TC06" description="Additional pages display once user logged in" finished-at="2018-11-27T09:03:33Z" duration-ms="1025" status="PASS">
          <reporter-output>
          </reporter-output>
        </test-method> <!-- TC06 -->
        <test-method signature="TC08()[pri:0, instance:Railway.LoginTest@76055d02]" started-at="2018-11-27T09:03:33Z" name="TC08" description="User can&#039;t login with an account hasn&#039;t been activated" finished-at="2018-11-27T09:03:34Z" duration-ms="432" status="PASS">
          <reporter-output>
          </reporter-output>
        </test-method> <!-- TC08 -->
        <test-method signature="TC09()[pri:0, instance:Railway.LoginTest@76055d02]" started-at="2018-11-27T09:03:34Z" name="TC09" description="User can change password" finished-at="2018-11-27T09:03:35Z" duration-ms="1269" status="FAIL">
          <exception class="java.lang.AssertionError">
            <message>
              <![CDATA[expected [Your password has been updated] but found [Your password has been updated!]]]>
            </message>
            <full-stacktrace>
              <![CDATA[java.lang.AssertionError: expected [Your password has been updated] but found [Your password has been updated!]
at org.testng.Assert.fail(Assert.java:96)
at org.testng.Assert.failNotEquals(Assert.java:776)
at org.testng.Assert.assertEqualsImpl(Assert.java:137)
at org.testng.Assert.assertEquals(Assert.java:118)
at org.testng.Assert.assertEquals(Assert.java:453)
at org.testng.Assert.assertEquals(Assert.java:463)
at Railway.LoginTest.TC09(LoginTest.java:93)
at java.base/jdk.internal.reflect.NativeMethodAccessorImpl.invoke0(Native Method)
at java.base/jdk.internal.reflect.NativeMethodAccessorImpl.invoke(NativeMethodAccessorImpl.java:62)
at java.base/jdk.internal.reflect.DelegatingMethodAccessorImpl.invoke(DelegatingMethodAccessorImpl.java:43)
at java.base/java.lang.reflect.Method.invoke(Method.java:566)
at org.testng.internal.MethodInvocationHelper.invokeMethod(MethodInvocationHelper.java:124)
at org.testng.internal.Invoker.invokeMethod(Invoker.java:580)
at org.testng.internal.Invoker.invokeTestMethod(Invoker.java:716)
at org.testng.internal.Invoker.invokeTestMethods(Invoker.java:988)
at org.testng.internal.TestMethodWorker.invokeTestMethods(TestMethodWorker.java:125)
at org.testng.internal.TestMethodWorker.run(TestMethodWorker.java:109)
at org.testng.TestRunner.privateRun(TestRunner.java:648)
at org.testng.TestRunner.run(TestRunner.java:505)
at org.testng.SuiteRunner.runTest(SuiteRunner.java:455)
at org.testng.SuiteRunner.runSequentially(SuiteRunner.java:450)
at org.testng.SuiteRunner.privateRun(SuiteRunner.java:415)
at org.testng.SuiteRunner.run(SuiteRunner.java:364)
at org.testng.SuiteRunnerWorker.runSuite(SuiteRunnerWorker.java:52)
at org.testng.SuiteRunnerWorker.run(SuiteRunnerWorker.java:84)
at org.testng.TestNG.runSuitesSequentially(TestNG.java:1208)
at org.testng.TestNG.runSuitesLocally(TestNG.java:1137)
at org.testng.TestNG.runSuites(TestNG.java:1049)
at org.testng.TestNG.run(TestNG.java:1017)
at org.testng.remote.AbstractRemoteTestNG.run(AbstractRemoteTestNG.java:114)
at org.testng.remote.RemoteTestNG.initAndRun(RemoteTestNG.java:251)
at org.testng.remote.RemoteTestNG.main(RemoteTestNG.java:77)
]]>
            </full-stacktrace>
          </exception> <!-- java.lang.AssertionError -->
          <reporter-output>
          </reporter-output>
        </test-method> <!-- TC09 -->
        <test-method is-config="true" signature="afterClass()[pri:0, instance:Railway.LoginTest@76055d02]" started-at="2018-11-27T09:03:35Z" name="afterClass" finished-at="2018-11-27T09:03:36Z" duration-ms="651" status="PASS">
          <reporter-output>
          </reporter-output>
        </test-method> <!-- afterClass -->
      </class> <!-- Railway.LoginTest -->
    </test> <!-- Default test -->
  </suite> <!-- Default suite -->
</testng-results>
