<?xml version="1.0" encoding="UTF-8"?>
<testng-results ignored="0" total="7" passed="5" failed="2" skipped="0">
  <reporter-output>
  </reporter-output>
  <suite started-at="2018-11-22T06:41:51Z" name="Default suite" finished-at="2018-11-22T06:42:28Z" duration-ms="37194">
    <groups>
    </groups>
    <test started-at="2018-11-22T06:41:51Z" name="Default test" finished-at="2018-11-22T06:42:28Z" duration-ms="37194">
      <class name="Railway.LoginTest">
        <test-method is-config="true" signature="beforeClass()[pri:0, instance:Railway.LoginTest@1f59a598]" started-at="2018-11-22T06:41:51Z" name="beforeClass" finished-at="2018-11-22T06:41:58Z" duration-ms="6940" status="PASS">
          <reporter-output>
          </reporter-output>
        </test-method> <!-- beforeClass -->
        <test-method signature="TC01()[pri:0, instance:Railway.LoginTest@1f59a598]" started-at="2018-11-22T06:41:58Z" name="TC01" description="User can log into Railway with valid username and password" finished-at="2018-11-22T06:42:09Z" duration-ms="10671" status="PASS">
          <reporter-output>
          </reporter-output>
        </test-method> <!-- TC01 -->
        <test-method signature="TC02()[pri:0, instance:Railway.LoginTest@1f59a598]" started-at="2018-11-22T06:42:09Z" name="TC02" description="User can&#039;t login with blank &#039;Username&#039; textbox" finished-at="2018-11-22T06:42:10Z" duration-ms="1396" status="PASS">
          <reporter-output>
          </reporter-output>
        </test-method> <!-- TC02 -->
        <test-method signature="TC03()[pri:0, instance:Railway.LoginTest@1f59a598]" started-at="2018-11-22T06:42:10Z" name="TC03" description="User cannot log into Railway with invalid password" finished-at="2018-11-22T06:42:12Z" duration-ms="1482" status="FAIL">
          <exception class="java.lang.AssertionError">
            <message>
              <![CDATA[
Expected is: 'There was a problem with your login and/or errors exist in your form.' displays
Actual is: 'Invalid username or password. Please try again.' displays
 expected [There was a problem with your login and/or errors exist in your form.] but found [Invalid username or password. Please try again.]]]>
            </message>
            <full-stacktrace>
              <![CDATA[java.lang.AssertionError: 
Expected is: 'There was a problem with your login and/or errors exist in your form.' displays
Actual is: 'Invalid username or password. Please try again.' displays
 expected [There was a problem with your login and/or errors exist in your form.] but found [Invalid username or password. Please try again.]
at org.testng.Assert.fail(Assert.java:96)
at org.testng.Assert.failNotEquals(Assert.java:776)
at org.testng.Assert.assertEqualsImpl(Assert.java:137)
at org.testng.Assert.assertEquals(Assert.java:118)
at org.testng.Assert.assertEquals(Assert.java:453)
at Utilities.Utilities.assertCheckTextElement(Utilities.java:49)
at Railway.LoginTest.TC03(LoginTest.java:54)
at java.base/jdk.internal.reflect.NativeMethodAccessorImpl.invoke0(Native Method)
at java.base/jdk.internal.reflect.NativeMethodAccessorImpl.invoke(NativeMethodAccessorImpl.java:62)
at java.base/jdk.internal.reflect.DelegatingMethodAccessorImpl.invoke(DelegatingMethodAccessorImpl.java:43)
at java.base/java.lang.reflect.Method.invoke(Method.java:566)
at org.testng.internal.MethodInvocationHelper.invokeMethod(MethodInvocationHelper.java:124)
at org.testng.internal.Invoker.invokeMethod(Invoker.java:580)
at org.testng.internal.Invoker.invokeTestMethod(Invoker.java:716)
at org.testng.internal.Invoker.invokeTestMethods(Invoker.java:988)
at org.testng.internal.TestMethodWorker.invokeTestMethods(TestMethodWorker.java:125)
at org.testng.internal.TestMethodWorker.run(TestMethodWorker.java:109)
at org.testng.TestRunner.privateRun(TestRunner.java:648)
at org.testng.TestRunner.run(TestRunner.java:505)
at org.testng.SuiteRunner.runTest(SuiteRunner.java:455)
at org.testng.SuiteRunner.runSequentially(SuiteRunner.java:450)
at org.testng.SuiteRunner.privateRun(SuiteRunner.java:415)
at org.testng.SuiteRunner.run(SuiteRunner.java:364)
at org.testng.SuiteRunnerWorker.runSuite(SuiteRunnerWorker.java:52)
at org.testng.SuiteRunnerWorker.run(SuiteRunnerWorker.java:84)
at org.testng.TestNG.runSuitesSequentially(TestNG.java:1208)
at org.testng.TestNG.runSuitesLocally(TestNG.java:1137)
at org.testng.TestNG.runSuites(TestNG.java:1049)
at org.testng.TestNG.run(TestNG.java:1017)
at org.testng.remote.AbstractRemoteTestNG.run(AbstractRemoteTestNG.java:114)
at org.testng.remote.RemoteTestNG.initAndRun(RemoteTestNG.java:251)
at org.testng.remote.RemoteTestNG.main(RemoteTestNG.java:77)
]]>
            </full-stacktrace>
          </exception> <!-- java.lang.AssertionError -->
          <reporter-output>
          </reporter-output>
        </test-method> <!-- TC03 -->
        <test-method signature="TC04()[pri:0, instance:Railway.LoginTest@1f59a598]" started-at="2018-11-22T06:42:12Z" name="TC04" description="Login page displays when un-logged User clicks on &#039;Book ticket&#039; tab" finished-at="2018-11-22T06:42:13Z" duration-ms="1132" status="PASS">
          <reporter-output>
          </reporter-output>
        </test-method> <!-- TC04 -->
        <test-method signature="TC05()[pri:0, instance:Railway.LoginTest@1f59a598]" started-at="2018-11-22T06:42:13Z" name="TC05" description="System shows message when user enters wrong password several times" finished-at="2018-11-22T06:42:17Z" duration-ms="4229" status="FAIL">
          <exception class="java.lang.AssertionError">
            <message>
              <![CDATA[
Expected is: 'You have used 4 out of 5 login attempts. After all 5 have been used, you will be unable to login for 15 minutes.' displays
Actual is: 'Invalid username or password. Please try again.' displays
 expected [You have used 4 out of 5 login attempts. After all 5 have been used, you will be unable to login for 15 minutes.] but found [Invalid username or password. Please try again.]]]>
            </message>
            <full-stacktrace>
              <![CDATA[java.lang.AssertionError: 
Expected is: 'You have used 4 out of 5 login attempts. After all 5 have been used, you will be unable to login for 15 minutes.' displays
Actual is: 'Invalid username or password. Please try again.' displays
 expected [You have used 4 out of 5 login attempts. After all 5 have been used, you will be unable to login for 15 minutes.] but found [Invalid username or password. Please try again.]
at org.testng.Assert.fail(Assert.java:96)
at org.testng.Assert.failNotEquals(Assert.java:776)
at org.testng.Assert.assertEqualsImpl(Assert.java:137)
at org.testng.Assert.assertEquals(Assert.java:118)
at org.testng.Assert.assertEquals(Assert.java:453)
at Utilities.Utilities.assertCheckTextElement(Utilities.java:49)
at Railway.LoginTest.TC05(LoginTest.java:69)
at java.base/jdk.internal.reflect.NativeMethodAccessorImpl.invoke0(Native Method)
at java.base/jdk.internal.reflect.NativeMethodAccessorImpl.invoke(NativeMethodAccessorImpl.java:62)
at java.base/jdk.internal.reflect.DelegatingMethodAccessorImpl.invoke(DelegatingMethodAccessorImpl.java:43)
at java.base/java.lang.reflect.Method.invoke(Method.java:566)
at org.testng.internal.MethodInvocationHelper.invokeMethod(MethodInvocationHelper.java:124)
at org.testng.internal.Invoker.invokeMethod(Invoker.java:580)
at org.testng.internal.Invoker.invokeTestMethod(Invoker.java:716)
at org.testng.internal.Invoker.invokeTestMethods(Invoker.java:988)
at org.testng.internal.TestMethodWorker.invokeTestMethods(TestMethodWorker.java:125)
at org.testng.internal.TestMethodWorker.run(TestMethodWorker.java:109)
at org.testng.TestRunner.privateRun(TestRunner.java:648)
at org.testng.TestRunner.run(TestRunner.java:505)
at org.testng.SuiteRunner.runTest(SuiteRunner.java:455)
at org.testng.SuiteRunner.runSequentially(SuiteRunner.java:450)
at org.testng.SuiteRunner.privateRun(SuiteRunner.java:415)
at org.testng.SuiteRunner.run(SuiteRunner.java:364)
at org.testng.SuiteRunnerWorker.runSuite(SuiteRunnerWorker.java:52)
at org.testng.SuiteRunnerWorker.run(SuiteRunnerWorker.java:84)
at org.testng.TestNG.runSuitesSequentially(TestNG.java:1208)
at org.testng.TestNG.runSuitesLocally(TestNG.java:1137)
at org.testng.TestNG.runSuites(TestNG.java:1049)
at org.testng.TestNG.run(TestNG.java:1017)
at org.testng.remote.AbstractRemoteTestNG.run(AbstractRemoteTestNG.java:114)
at org.testng.remote.RemoteTestNG.initAndRun(RemoteTestNG.java:251)
at org.testng.remote.RemoteTestNG.main(RemoteTestNG.java:77)
]]>
            </full-stacktrace>
          </exception> <!-- java.lang.AssertionError -->
          <reporter-output>
          </reporter-output>
        </test-method> <!-- TC05 -->
        <test-method signature="TC06()[pri:0, instance:Railway.LoginTest@1f59a598]" started-at="2018-11-22T06:42:17Z" name="TC06" description="Additional pages display once user logged in" finished-at="2018-11-22T06:42:22Z" duration-ms="5417" status="PASS">
          <reporter-output>
          </reporter-output>
        </test-method> <!-- TC06 -->
        <test-method signature="TC07()[pri:0, instance:Railway.LoginTest@1f59a598]" started-at="2018-11-22T06:42:22Z" name="TC07" description="User can create new account" finished-at="2018-11-22T06:42:28Z" duration-ms="5300" status="PASS">
          <reporter-output>
          </reporter-output>
        </test-method> <!-- TC07 -->
        <test-method is-config="true" signature="afterClass()[pri:0, instance:Railway.LoginTest@1f59a598]" started-at="2018-11-22T06:42:28Z" name="afterClass" finished-at="2018-11-22T06:42:28Z" duration-ms="603" status="PASS">
          <reporter-output>
          </reporter-output>
        </test-method> <!-- afterClass -->
      </class> <!-- Railway.LoginTest -->
    </test> <!-- Default test -->
  </suite> <!-- Default suite -->
</testng-results>
