<?xml version="1.0" encoding="UTF-8"?>
<!-- Generated by org.testng.reporters.JUnitReportReporter -->
<testsuite hostname="LGDN18-1071-W10" failures="2" tests="7" name="Railway.LoginTest" time="24.206" errors="0" timestamp="22 Nov 2018 03:19:31 GMT" skipped="0">
  <testcase classname="Railway.LoginTest" name="TC01" time="5.320"/>
  <testcase classname="Railway.LoginTest" name="TC03" time="1.517">
    <failure message="
Expected is: &#039;There was a problem with your login and/or errors exist in your form.&#039; displays
Actual is: &#039;Invalid username or password. Please try again.&#039; displays
 expected [There was a problem with your login and/or errors exist in your form.] but found [Invalid username or password. Please try again.]" type="java.lang.AssertionError">
      <![CDATA[java.lang.AssertionError: 
Expected is: 'There was a problem with your login and/or errors exist in your form.' displays
Actual is: 'Invalid username or password. Please try again.' displays
 expected [There was a problem with your login and/or errors exist in your form.] but found [Invalid username or password. Please try again.]
at org.testng.Assert.fail(Assert.java:96)
at org.testng.Assert.failNotEquals(Assert.java:776)
at org.testng.Assert.assertEqualsImpl(Assert.java:137)
at org.testng.Assert.assertEquals(Assert.java:118)
at org.testng.Assert.assertEquals(Assert.java:453)
at Utilities.Utilities.assertCheckTextElement(Utilities.java:49)
at Railway.LoginTest.TC03(LoginTest.java:54)
at java.base/jdk.internal.reflect.NativeMethodAccessorImpl.invoke0(Native Method)
at java.base/jdk.internal.reflect.NativeMethodAccessorImpl.invoke(NativeMethodAccessorImpl.java:62)
at java.base/jdk.internal.reflect.DelegatingMethodAccessorImpl.invoke(DelegatingMethodAccessorImpl.java:43)
at java.base/java.lang.reflect.Method.invoke(Method.java:566)
at org.testng.internal.MethodInvocationHelper.invokeMethod(MethodInvocationHelper.java:124)
at org.testng.internal.Invoker.invokeMethod(Invoker.java:580)
at org.testng.internal.Invoker.invokeTestMethod(Invoker.java:716)
at org.testng.internal.Invoker.invokeTestMethods(Invoker.java:988)
at org.testng.internal.TestMethodWorker.invokeTestMethods(TestMethodWorker.java:125)
at org.testng.internal.TestMethodWorker.run(TestMethodWorker.java:109)
at org.testng.TestRunner.privateRun(TestRunner.java:648)
at org.testng.TestRunner.run(TestRunner.java:505)
at org.testng.SuiteRunner.runTest(SuiteRunner.java:455)
at org.testng.SuiteRunner.runSequentially(SuiteRunner.java:450)
at org.testng.SuiteRunner.privateRun(SuiteRunner.java:415)
at org.testng.SuiteRunner.run(SuiteRunner.java:364)
at org.testng.SuiteRunnerWorker.runSuite(SuiteRunnerWorker.java:52)
at org.testng.SuiteRunnerWorker.run(SuiteRunnerWorker.java:84)
at org.testng.TestNG.runSuitesSequentially(TestNG.java:1208)
at org.testng.TestNG.runSuitesLocally(TestNG.java:1137)
at org.testng.TestNG.runSuites(TestNG.java:1049)
at org.testng.TestNG.run(TestNG.java:1017)
at org.testng.remote.AbstractRemoteTestNG.run(AbstractRemoteTestNG.java:114)
at org.testng.remote.RemoteTestNG.initAndRun(RemoteTestNG.java:251)
at org.testng.remote.RemoteTestNG.main(RemoteTestNG.java:77)
]]>
    </failure>
  </testcase> <!-- TC03 -->
  <testcase classname="Railway.LoginTest" name="TC02" time="1.370"/>
  <testcase classname="Railway.LoginTest" name="TC07" time="5.028"/>
  <testcase classname="Railway.LoginTest" name="TC05" time="4.273">
    <failure message="
Expected is: &#039;You have used 4 out of 5 login attempts. After all 5 have been used, you will be unable to login for 15 minutes.&#039; displays
Actual is: &#039;Invalid username or password. Please try again.&#039; displays
 expected [You have used 4 out of 5 login attempts. After all 5 have been used, you will be unable to login for 15 minutes.] but found [Invalid username or password. Please try again.]" type="java.lang.AssertionError">
      <![CDATA[java.lang.AssertionError: 
Expected is: 'You have used 4 out of 5 login attempts. After all 5 have been used, you will be unable to login for 15 minutes.' displays
Actual is: 'Invalid username or password. Please try again.' displays
 expected [You have used 4 out of 5 login attempts. After all 5 have been used, you will be unable to login for 15 minutes.] but found [Invalid username or password. Please try again.]
at org.testng.Assert.fail(Assert.java:96)
at org.testng.Assert.failNotEquals(Assert.java:776)
at org.testng.Assert.assertEqualsImpl(Assert.java:137)
at org.testng.Assert.assertEquals(Assert.java:118)
at org.testng.Assert.assertEquals(Assert.java:453)
at Utilities.Utilities.assertCheckTextElement(Utilities.java:49)
at Railway.LoginTest.TC05(LoginTest.java:69)
at java.base/jdk.internal.reflect.NativeMethodAccessorImpl.invoke0(Native Method)
at java.base/jdk.internal.reflect.NativeMethodAccessorImpl.invoke(NativeMethodAccessorImpl.java:62)
at java.base/jdk.internal.reflect.DelegatingMethodAccessorImpl.invoke(DelegatingMethodAccessorImpl.java:43)
at java.base/java.lang.reflect.Method.invoke(Method.java:566)
at org.testng.internal.MethodInvocationHelper.invokeMethod(MethodInvocationHelper.java:124)
at org.testng.internal.Invoker.invokeMethod(Invoker.java:580)
at org.testng.internal.Invoker.invokeTestMethod(Invoker.java:716)
at org.testng.internal.Invoker.invokeTestMethods(Invoker.java:988)
at org.testng.internal.TestMethodWorker.invokeTestMethods(TestMethodWorker.java:125)
at org.testng.internal.TestMethodWorker.run(TestMethodWorker.java:109)
at org.testng.TestRunner.privateRun(TestRunner.java:648)
at org.testng.TestRunner.run(TestRunner.java:505)
at org.testng.SuiteRunner.runTest(SuiteRunner.java:455)
at org.testng.SuiteRunner.runSequentially(SuiteRunner.java:450)
at org.testng.SuiteRunner.privateRun(SuiteRunner.java:415)
at org.testng.SuiteRunner.run(SuiteRunner.java:364)
at org.testng.SuiteRunnerWorker.runSuite(SuiteRunnerWorker.java:52)
at org.testng.SuiteRunnerWorker.run(SuiteRunnerWorker.java:84)
at org.testng.TestNG.runSuitesSequentially(TestNG.java:1208)
at org.testng.TestNG.runSuitesLocally(TestNG.java:1137)
at org.testng.TestNG.runSuites(TestNG.java:1049)
at org.testng.TestNG.run(TestNG.java:1017)
at org.testng.remote.AbstractRemoteTestNG.run(AbstractRemoteTestNG.java:114)
at org.testng.remote.RemoteTestNG.initAndRun(RemoteTestNG.java:251)
at org.testng.remote.RemoteTestNG.main(RemoteTestNG.java:77)
]]>
    </failure>
  </testcase> <!-- TC05 -->
  <testcase classname="Railway.LoginTest" name="TC04" time="1.146"/>
  <testcase classname="Railway.LoginTest" name="TC06" time="5.552"/>
</testsuite> <!-- Railway.LoginTest -->
